root_script: extract_edges.sbat
Requirement already satisfied: decorator==5.1.0 in /home/casonk/.local/lib/python3.9/site-packages (5.1.0)
WARNING: You are using pip version 22.0.4; however, version 22.3 is available.
You should consider upgrading via the '/sw/pkgs/arc/python/3.9.12/bin/python3.9 -m pip install --upgrade pip' command.
Requirement already satisfied: pandas==1.4.2 in /home/casonk/.local/lib/python3.9/site-packages (1.4.2)
Requirement already satisfied: pytz>=2020.1 in /home/casonk/.local/lib/python3.9/site-packages (from pandas==1.4.2) (2022.1)
Requirement already satisfied: python-dateutil>=2.8.1 in /home/casonk/.local/lib/python3.9/site-packages (from pandas==1.4.2) (2.8.2)
Requirement already satisfied: numpy>=1.18.5 in /home/casonk/.local/lib/python3.9/site-packages (from pandas==1.4.2) (1.22.3)
Requirement already satisfied: six>=1.5 in /sw/pkgs/arc/python/3.9.12/lib/python3.9/site-packages (from python-dateutil>=2.8.1->pandas==1.4.2) (1.16.0)
WARNING: You are using pip version 22.0.4; however, version 22.3 is available.
You should consider upgrading via the '/sw/pkgs/arc/python/3.9.12/bin/python3.9 -m pip install --upgrade pip' command.

/sw/pkgs/arc/python/3.9.12/bin/python

spinning up at: Sat Oct 29 06:53:15 EDT 2022
Job submitted by gl-login2.arc-ts.umich.edu
Job ID 44235557
Running on gl[3274-3278]
Running in /home/casonk/path/mmani_root/mmani0/shared_data/pushshift_python/Great_Lakes_HPC/pys/insurrection 

Traceback (most recent call last):
  File "/gpfs/accounts/mmani_root/mmani0/shared_data/pushshift_python/Great_Lakes_HPC/pys/insurrection/extract_edges.py", line 158, in <module>
    unraw_counter(auth_net, 20)
  File "/gpfs/accounts/mmani_root/mmani0/shared_data/pushshift_python/Great_Lakes_HPC/pys/insurrection/extract_edges.py", line 102, in unraw_counter
    tgt_users = src_counts[(tgt_counts <= max_user_posts)].index.to_series()
  File "/home/casonk/.local/lib/python3.9/site-packages/pandas/core/series.py", line 980, in __getitem__
    key = check_bool_indexer(self.index, key)
  File "/home/casonk/.local/lib/python3.9/site-packages/pandas/core/indexing.py", line 2383, in check_bool_indexer
    raise IndexingError(
pandas.core.indexing.IndexingError: Unalignable boolean Series provided as indexer (index of the boolean Series and of the indexed object do not match).
spinning down at: Sat Oct 29 06:53:34 EDT 2022
